Workbook

Sheet Graficas
B2: Bonanza
B3: ESTATUS UNIDADES PARA ENTREGA
G5: ENTREGADAS A PVTA | J5: 20.33
C6: UNIDADES | D6: VTAS USD | E6: COB USD | F6: X COB USD | G6: RECIBIDO | H6: ENTREGADO | I6: X COB REC USD | J6: VAL LIB USD | K6: DIF
B7: SOLD | C7: =COUNTIF(Bonanza!$O$7:$O$197,Graficas!$B7) -> 184 | D7: =SUMIFS(Bonanza!$P:$P,Bonanza!$O:$O,Graficas!$B7) -> 37005200 | E7: =SUMIFS(Bonanza!$R:$R,Bonanza!$O:$O,Graficas!$B7) -> 16304488 | F7: =D7-E7 -> 20700712 | G7: =COUNTIFS(Bonanza!$AE:$AE,Graficas!G$6,Bonanza!$O:$O,Graficas!$B7) -> 0 | H7: =COUNTIFS(Bonanza!$AE:$AE,Graficas!H$6,Bonanza!$O:$O,Graficas!$B7) -> 0 | I7: =SUMIFS(Bonanza!$T:$T,Bonanza!$O:$O,Graficas!$B7,Bonanza!$AE:$AE,Graficas!$G6) -> 0 | J7: =SUMIFS(Bonanza!$X:$X,Bonanza!$O:$O,Graficas!$B7,Bonanza!$AE:$AE,Graficas!$G$6)/20.33 -> 0 | K7: =I7-J7 -> 0
B8: AVAILABLE | C8: =COUNTIF(Bonanza!$O$7:$O$197,Graficas!$B8) -> 7 | D8: =SUMIFS(Bonanza!$P:$P,Bonanza!$O:$O,Graficas!$B8) -> 0 | E8: =SUMIFS(Bonanza!$R:$R,Bonanza!$O:$O,Graficas!$B8) -> 0 | F8: =D8-E8 -> 0 | G8: =COUNTIFS(Bonanza!$AE:$AE,Graficas!G$6,Bonanza!$O:$O,Graficas!$B8) -> 0 | H8: =COUNTIFS(Bonanza!$AE:$AE,Graficas!H$6,Bonanza!$O:$O,Graficas!$B8) -> 0 | I8: =SUMIFS(Bonanza!$T:$T,Bonanza!$O:$O,Graficas!$B8,Bonanza!$AE:$AE,Graficas!$G6) -> 0 | J8: =SUMIFS(Bonanza!$X:$X,Bonanza!$O:$O,Graficas!$B8,Bonanza!$AE:$AE,Graficas!$G$6)/20.33 -> 0 | K8: =I8-J8 -> 0
B10: TOTALES | C10: =SUM(C7:C9) -> 191 | D10: =SUM(D7:D9) -> 37005200 | E10: =SUM(E7:E9) -> 16304488 | F10: =SUM(F7:F9) -> 20700712 | G10: =SUM(G7:G9) -> 0 | H10: =SUM(H7:H9) -> 0 | I10: =SUM(I7:I9) -> 0 | J10: =SUM(J7:J9) -> 0 | K10: =SUM(K7:K9) -> 0

Sheet RESUMEN
K1: 18.5
B4: USD | C4: UNIDS | D4: RETA OP FIN | E4: RETA | F4: GENERAL | H4: MXN | J4: RETA OP FIN | K4: RETA | L4: GENERAL | N4: BONANZA | P4: RETA OP FIN | Q4: RETA | R4: GENERAL
B5: SOLD | C5: =COUNTIFS(Bonanza!$O:$O,RESUMEN!$B5,Bonanza!$D:$D,RESUMEN!$B$4) -> 123 | D5: =COUNTIFS(Bonanza!$O:$O,RESUMEN!$B5,Bonanza!$D:$D,RESUMEN!$B$4,Bonanza!$M:$M,RESUMEN!D$4) -> 98 | E5: =COUNTIFS(Bonanza!$O:$O,RESUMEN!$B5,Bonanza!$D:$D,RESUMEN!$B$4,Bonanza!$M:$M,RESUMEN!E$4) -> 25 | F5: =COUNTIFS(Bonanza!$O:$O,RESUMEN!$B5,Bonanza!$D:$D,RESUMEN!$B$4,Bonanza!$M:$M,RESUMEN!F$4) -> 0 | H5: SOLD | I5: =COUNTIFS(Bonanza!$O:$O,RESUMEN!$H5,Bonanza!$D:$D,RESUMEN!$H$4) -> 61 | J5: =COUNTIFS(Bonanza!$O:$O,RESUMEN!$H5,Bonanza!$D:$D,RESUMEN!$H$4,Bonanza!$M:$M,RESUMEN!D$4) -> 0 | K5: =COUNTIFS(Bonanza!$O:$O,RESUMEN!$H5,Bonanza!$D:$D,RESUMEN!$H$4,Bonanza!$M:$M,RESUMEN!E$4) -> 0 | L5: =COUNTIFS(Bonanza!$O:$O,RESUMEN!$H5,Bonanza!$D:$D,RESUMEN!$H$4,Bonanza!$M:$M,RESUMEN!F$4) -> 61 | N5: SOLD | O5: =C5+I5 -> 184 | P5: =D5+J5 -> 98 | Q5: =E5+K5 -> 25 | R5: =F5+L5 -> 61
B6: AVAILABLE | C6: =COUNTIFS(Bonanza!$O:$O,RESUMEN!$B6,Bonanza!$D:$D,RESUMEN!$B$4) -> 0 | D6: =COUNTIFS(Bonanza!$O:$O,RESUMEN!$B6,Bonanza!$D:$D,RESUMEN!$B$4,Bonanza!$M:$M,RESUMEN!D$4) -> 0 | E6: =COUNTIFS(Bonanza!$O:$O,RESUMEN!$B6,Bonanza!$D:$D,RESUMEN!$B$4,Bonanza!$M:$M,RESUMEN!E$4) -> 0 | F6: =COUNTIFS(Bonanza!$O:$O,RESUMEN!$B6,Bonanza!$D:$D,RESUMEN!$B$4,Bonanza!$M:$M,RESUMEN!F$4) -> 0 | H6: AVAILABLE | I6: =COUNTIFS(Bonanza!$O:$O,RESUMEN!$H6,Bonanza!$D:$D,RESUMEN!$H$4) -> 7 | J6: =COUNTIFS(Bonanza!$O:$O,RESUMEN!$H6,Bonanza!$D:$D,RESUMEN!$H$4,Bonanza!$M:$M,RESUMEN!D$4) -> 0 | K6: =COUNTIFS(Bonanza!$O:$O,RESUMEN!$H6,Bonanza!$D:$D,RESUMEN!$H$4,Bonanza!$M:$M,RESUMEN!E$4) -> 0 | L6: =COUNTIFS(Bonanza!$O:$O,RESUMEN!$H6,Bonanza!$D:$D,RESUMEN!$H$4,Bonanza!$M:$M,RESUMEN!F$4) -> 7 | N6: AVAILABLE | O6: =C6+I6 -> 7 | P6: =D6+J6 -> 0 | Q6: =E6+K6 -> 0 | R6: =F6+L6 -> 7
B7: DESACTIVADO | C7: =COUNTIFS(Bonanza!$O:$O,RESUMEN!$B7,Bonanza!$D:$D,RESUMEN!$B$4) -> 0 | D7: =COUNTIFS(Bonanza!$O:$O,RESUMEN!$B7,Bonanza!$D:$D,RESUMEN!$B$4,Bonanza!$M:$M,RESUMEN!D$4) -> 0 | E7: =COUNTIFS(Bonanza!$O:$O,RESUMEN!$B7,Bonanza!$D:$D,RESUMEN!$B$4,Bonanza!$M:$M,RESUMEN!E$4) -> 0 | F7: =COUNTIFS(Bonanza!$O:$O,RESUMEN!$B7,Bonanza!$D:$D,RESUMEN!$B$4,Bonanza!$M:$M,RESUMEN!F$4) -> 0 | H7: DESACTIVADO | I7: =COUNTIFS(Bonanza!$O:$O,RESUMEN!$H7,Bonanza!$D:$D,RESUMEN!$H$4) -> 0 | J7: =COUNTIFS(Bonanza!$O:$O,RESUMEN!$H7,Bonanza!$D:$D,RESUMEN!$H$4,Bonanza!$M:$M,RESUMEN!D$4) -> 0 | K7: =COUNTIFS(Bonanza!$O:$O,RESUMEN!$H7,Bonanza!$D:$D,RESUMEN!$H$4,Bonanza!$M:$M,RESUMEN!E$4) -> 0 | L7: =COUNTIFS(Bonanza!$O:$O,RESUMEN!$H7,Bonanza!$D:$D,RESUMEN!$H$4,Bonanza!$M:$M,RESUMEN!F$4) -> 0 | N7: DESACTIVADO | O7: =C7+I7 -> 0 | P7: =D7+J7 -> 0 | Q7: =E7+K7 -> 0 | R7: =F7+L7 -> 0
C8: =COUNTIFS(Bonanza!$O:$O,RESUMEN!$B8,Bonanza!$D:$D,RESUMEN!$B$4) -> 0 | D8: =COUNTIFS(Bonanza!$O:$O,RESUMEN!$B8,Bonanza!$D:$D,RESUMEN!$B$4,Bonanza!$M:$M,RESUMEN!D$4) -> 0 | E8: =COUNTIFS(Bonanza!$O:$O,RESUMEN!$B8,Bonanza!$D:$D,RESUMEN!$B$4,Bonanza!$M:$M,RESUMEN!E$4) -> 0 | F8: =COUNTIFS(Bonanza!$O:$O,RESUMEN!$B8,Bonanza!$D:$D,RESUMEN!$B$4,Bonanza!$M:$M,RESUMEN!F$4) -> 0 | I8: =COUNTIFS(Bonanza!$O:$O,RESUMEN!$H8,Bonanza!$D:$D,RESUMEN!$H$4) -> 0 | J8: =COUNTIFS(Bonanza!$O:$O,RESUMEN!$H8,Bonanza!$D:$D,RESUMEN!$H$4,Bonanza!$M:$M,RESUMEN!D$4) -> 0 | K8: =COUNTIFS(Bonanza!$O:$O,RESUMEN!$H8,Bonanza!$D:$D,RESUMEN!$H$4,Bonanza!$M:$M,RESUMEN!E$4) -> 0 | L8: =COUNTIFS(Bonanza!$O:$O,RESUMEN!$H8,Bonanza!$D:$D,RESUMEN!$H$4,Bonanza!$M:$M,RESUMEN!F$4) -> 0 | O8: =C8+I8 -> 0 | P8: =D8+J8 -> 0 | Q8: =E8+K8 -> 0 | R8: =F8+L8 -> 0
B9: TOTAL | C9: =SUM(C5:C8) -> 123 | D9: =SUM(D5:D8) -> 98 | E9: =SUM(E5:E8) -> 25 | F9: =SUM(F5:F8) -> 0 | H9: TOTAL | I9: =SUM(I5:I8) -> 68 | J9: =SUM(J5:J8) -> 0 | K9: =SUM(K5:K8) -> 0 | L9: =SUM(L5:L8) -> 68 | N9: TOTAL | O9: =SUM(O5:O8) -> 191 | P9: =SUM(P5:P8) -> 98 | Q9: =SUM(Q5:Q8) -> 25 | R9: =SUM(R5:R8) -> 68
B12: USD | C12: VENTAS | D12: COBRADO | E12: X COBRAR | F12: X FINANCIAR | G12: X COBRAR RECURSO PROPIO
B13: RETA OP FIN | C13: =SUMIF(Bonanza!$M:$M,RESUMEN!$B13,Bonanza!$P:$P) -> 29786800 | D13: =SUMIF(Bonanza!$M:$M,RESUMEN!$B13,Bonanza!$R:$R) -> 13198699 | E13: =SUMIF(Bonanza!$M:$M,RESUMEN!$B13,Bonanza!$T:$T) -> 16588101 | F13: =SUMIF(Bonanza!$M:$M,RESUMEN!$B13,Bonanza!#REF!) -> #REF! | G13: =E13-F13 -> #REF!
B14: RETA | C14: =SUMIF(Bonanza!$M:$M,RESUMEN!$B14,Bonanza!$P:$P) -> 7218400 | D14: =SUMIF(Bonanza!$M:$M,RESUMEN!$B14,Bonanza!$R:$R) -> 3105789 | E14: =SUMIF(Bonanza!$M:$M,RESUMEN!$B14,Bonanza!$T:$T) -> 4112611 | F14: =SUMIF(Bonanza!$M:$M,RESUMEN!$B14,Bonanza!#REF!) -> #REF! | G14: =E14-F14 -> #REF!
B15: GENERAL | C15: =SUMIF(Bonanza!$M:$M,RESUMEN!$B15,Bonanza!$P:$P) -> 0 | D15: =SUMIF(Bonanza!$M:$M,RESUMEN!$B15,Bonanza!$R:$R) -> 0 | E15: =SUMIF(Bonanza!$M:$M,RESUMEN!$B15,Bonanza!$T:$T) -> 0 | F15: =SUMIF(Bonanza!$M:$M,RESUMEN!$B15,Bonanza!#REF!) -> #REF! | G15: =E15-F15 -> #REF!
C16: =SUMIF(Bonanza!$M:$M,RESUMEN!$B16,Bonanza!$P:$P) -> 0 | D16: =SUMIF(Bonanza!$M:$M,RESUMEN!$B16,Bonanza!$R:$R) -> 0 | E16: =SUMIF(Bonanza!$M:$M,RESUMEN!$B16,Bonanza!$T:$T) -> 0 | F16: =SUMIF(Bonanza!$M:$M,RESUMEN!$B16,Bonanza!#REF!) -> #REF! | G16: =E16-F16 -> #REF!
B17: TOTAL | C17: =SUM(C13:C16) -> 37005200 | D17: =SUM(D13:D16) -> 16304488 | E17: =SUM(E13:E16) -> 20700712 | F17: =SUM(F13:F16) -> #REF! | G17: =SUM(G13:G16) -> #REF!
B19: MXN | C19: VENTAS | D19: COBRADO | E19: X COBRAR | F19: X FINANCIAR | G19: X COBRAR RECURSO PROPIO
B20: RETA OP FIN | C20: =SUMIFS(Bonanza!$Q:$Q,Bonanza!$M:$M,RESUMEN!$B20,Bonanza!$D:$D,RESUMEN!$B$19) -> 0 | D20: =SUMIFS(Bonanza!$S:$S,Bonanza!$M:$M,RESUMEN!$B20,Bonanza!$D:$D,RESUMEN!$B$19) -> 0 | E20: =SUMIFS(Bonanza!$U:$U,Bonanza!$M:$M,RESUMEN!$B20,Bonanza!$D:$D,RESUMEN!$B$19) -> 0 | F20: =SUMIFS(Bonanza!#REF!,Bonanza!$M:$M,RESUMEN!$B20,Bonanza!$D:$D,RESUMEN!$B$19) -> #REF! | G20: =E20-F20 -> #REF!
B21: RETA | C21: =SUMIFS(Bonanza!$Q:$Q,Bonanza!$M:$M,RESUMEN!$B21,Bonanza!$D:$D,RESUMEN!$B$19) -> 0 | D21: =SUMIFS(Bonanza!$S:$S,Bonanza!$M:$M,RESUMEN!$B21,Bonanza!$D:$D,RESUMEN!$B$19) -> 0 | E21: =SUMIFS(Bonanza!$U:$U,Bonanza!$M:$M,RESUMEN!$B21,Bonanza!$D:$D,RESUMEN!$B$19) -> 0 | F21: =SUMIFS(Bonanza!#REF!,Bonanza!$M:$M,RESUMEN!$B21,Bonanza!$D:$D,RESUMEN!$B$19) -> #REF! | G21: =E21-F21 -> #REF!
B22: GENERAL | C22: =SUMIFS(Bonanza!$Q:$Q,Bonanza!$M:$M,RESUMEN!$B22,Bonanza!$D:$D,RESUMEN!$B$19) -> 5.6820131e+08 | D22: =SUMIFS(Bonanza!$S:$S,Bonanza!$M:$M,RESUMEN!$B22,Bonanza!$D:$D,RESUMEN!$B$19) -> 2.9718172e+08 | E22: =SUMIFS(Bonanza!$U:$U,Bonanza!$M:$M,RESUMEN!$B22,Bonanza!$D:$D,RESUMEN!$B$19) -> 2.7101958e+08 | F22: =SUMIFS(Bonanza!#REF!,Bonanza!$M:$M,RESUMEN!$B22,Bonanza!$D:$D,RESUMEN!$B$19) -> #REF! | G22: =E22-F22 -> #REF!
C23: =SUMIF(Bonanza!$M:$M,RESUMEN!$B23,Bonanza!$Q:$Q) -> 0 | D23: =SUMIFS(Bonanza!$S:$S,Bonanza!$M:$M,RESUMEN!$B23,Bonanza!$D:$D,RESUMEN!$B$19) -> 0 | E23: =SUMIFS(Bonanza!$U:$U,Bonanza!$M:$M,RESUMEN!$B23,Bonanza!$D:$D,RESUMEN!$B$19) -> 0 | F23: =SUMIFS(Bonanza!#REF!,Bonanza!$M:$M,RESUMEN!$B23,Bonanza!$D:$D,RESUMEN!$B$19) -> #REF! | G23: =E23-F23 -> #REF!
B24: TOTAL | C24: =SUM(C20:C23) -> 5.6820131e+08 | D24: =SUM(D20:D23) -> 2.9718172e+08 | E24: =SUM(E20:E23) -> 2.7101958e+08 | F24: =SUM(F20:F23) -> #REF! | G24: =SUM(G20:G23) -> #REF!
B26: BONANZA MXN | C26: VENTAS | D26: COBRADO | E26: X COBRAR | F26: X FINANCIAR | G26: X COBRAR RECURSO PROPIO
B27: RETA OP FIN | C27: =SUM((C13*$K$1)+C20) -> 551055800 | D27: =SUM((D13*$K$1)+D20) -> 2.4417593e+08 | E27: =SUM((E13*$K$1)+E20) -> 3.0687987e+08 | F27: =SUM((F13*$K$1)+F20) -> #REF! | G27: =SUM((G13*$K$1)+G20) -> #REF!
B28: RETA | C28: =SUM((C14*$K$1)+C21) -> 133540400 | D28: =SUM((D14*$K$1)+D21) -> 57457096 | E28: =SUM((E14*$K$1)+E21) -> 76083304 | F28: =SUM((F14*$K$1)+F21) -> #REF! | G28: =SUM((G14*$K$1)+G21) -> #REF!
B29: GENERAL | C29: =SUM((C15*$K$1)+C22) -> 5.6820131e+08 | D29: =SUM((D15*$K$1)+D22) -> 2.9718172e+08 | E29: =SUM((E15*$K$1)+E22) -> 2.7101958e+08 | F29: =SUM((F15*$K$1)+F22) -> #REF! | G29: =SUM((G15*$K$1)+G22) -> #REF!
C30: =SUM((C16*$K$1)+C23) -> 0 | D30: =SUM((D16*$K$1)+D23) -> 0 | E30: =SUM((E16*$K$1)+E23) -> 0 | F30: =SUM((F16*$K$1)+F23) -> #REF! | G30: =SUM((G16*$K$1)+G23) -> #REF!
B31: TOTAL | C31: =SUM(C27:C30) -> 1.2527975e+09 | D31: =SUM(D27:D30) -> 5.9881475e+08 | E31: =SUM(E27:E30) -> 6.5398276e+08 | F31: =SUM(F27:F30) -> #REF! | G31: =SUM(G27:G30) -> #REF!

Sheet Bonanza
B2: Relación de Departamentos para entrega | Z2: SUPERAVIT/DEFICIT
U3: 18.5 | W3: CREDITO | Y3: =X3-Y4 -> 0 | Z3: =U4-Y3 -> 6.5398276e+08
C4: =SUBTOTAL(3,C7:C197) -> 191 | M4: =SUBTOTAL(3,M7:M197) -> 191 | P4: =SUBTOTAL(9,P7:P197) -> 37005200 | Q4: =SUBTOTAL(9,Q7:Q197) -> 1.2527975e+09 | R4: =SUBTOTAL(9,R7:R197) -> 16304488 | S4: =SUBTOTAL(9,S7:S197) -> 2.9718172e+08 | T4: =SUBTOTAL(9,T7:T197) -> 20700712 | U4: =SUBTOTAL(9,U7:U197) -> 6.5398276e+08 | W4: =SUBTOTAL(3,$W$7:$W$197) -> 98 | X4: =SUBTOTAL(9,X7:X197) -> #N/A | Y4: =SUM(Y7:Y197) -> 0 | Z4: =SUBTOTAL(9,Z7:Z197) -> #N/A | AE4: =SUBTOTAL(3,AE7:AE197) -> 0
B5: VENTAS | X5: BANCO | AB5: LEGAL | AE5: POSTVENTA
B6: No. | C6: unit_id | D6: MONEDA | E6: TYPE | F6: NOMBRE (S) | G6: APELLIDO 1 | H6: APELLIDO 2 | I6: ALIAS / RAZON SOCIAL | J6: @mail | K6: LADA | L6: Telefono | M6: TIPO CLIENTE | N6: TIPO CONTRATO | O6: STATUS SISTEMA | P6: MONTO DE VENTA USD | Q6: MONTO DE VENTA MN | R6: PAGADO USD | S6: PAGADO MN | T6: SALDO USD | U6: SALDO MN | V6: FECHA COBRO SALDO | W6: FORMA PAGO | X6: VALOR LIBERACION | Y6: PAGADO LIBERACION | Z6: X PAGAR | AA6: FECHA LIBERACIÓN | AB6: ESCRITURACION | AC6: FECHA ESCRITURACION | AD6: NOTARIA | AE6: STATUS SOS | AF6: FECHA SEGÚN CONTRATO | AG6: ÚLTIMO CONTACTO SOS | AI6: FECHA ENTREGA OBRA | AJ6: estatus_obra | AK6: FECHA ENTREGA CLIENTE | AL6: COMENTARIOS | AM6: TICKET | AO6: Departamento | AP6: Fecha de Control calidad | AQ6: Fecha posible de entrega final | AR6: Tipo de dueño | AS6: Estatus
B7: 1 | C7: 1 | D7: USD | F7: CHRISTOPHER MICHAEL | G7: DAVIS | M7: RETA | O7: SOLD | P7: 375000 | Q7: =P7*$U$3 -> 6937500 | R7: 374500 | T7: =P7-R7 -> 500 | U7: =T7*U$3 -> 9250 | X7: =VLOOKUP(C7,Banorte!F:K,6,FALSE) -> #N/A | Z7: =X7-Y7 -> #N/A | AI7: 46265 | AO7: V01 | AP7: 46227 | AQ7: 46265 | AR7: RETA | AS7: PAGADO
B8: 124 | C8: 2 | D8: MXN | F8: CLAUDIA | G8: RASCON | H8: BUSTILLOS | M8: GENERAL | O8: SOLD | Q8: 10990000 | S8: 3297132.1 | U8: =Q8-S8 -> 7692867.8 | X8: =VLOOKUP(C8,Banorte!F:K,6,FALSE) -> #N/A | Z8: =X8-Y8 -> #N/A | AI8: 46265 | AO8: V02 | AP8: 46227 | AQ8: 46265 | AR8: GENERAL
B9: 125 | C9: 3 | D9: MXN | F9: SERGIO | G9: RASCON | H9: BUSTILLOS | M9: GENERAL | O9: SOLD | Q9: 13720000 | S9: 13720000 | U9: =Q9-S9 -> 0 | X9: =VLOOKUP(C9,Banorte!F:K,6,FALSE) -> #N/A | Z9: =X9-Y9 -> #N/A | AI9: 46265 | AO9: V03 | AP9: 46227 | AQ9: 46265 | AR9: GENERAL | AS9: PAGADO
B10: 2 | C10: 4 | D10: USD | F10: JOHN MARK | G10: JONES | M10: RETA OP FIN | O10: SOLD | P10: 375000 | Q10: =P10*$U$3 -> 6937500 | R10: 133220 | T10: =P10-R10 -> 241780 | U10: =T10*U$3 -> 4472930 | W10: CREDITO RETA | X10: =VLOOKUP(C10,Banorte!F:K,6,FALSE) -> #N/A | Z10: =X10-Y10 -> #N/A | AI10: 46265 | AO10: V04 | AP10: 46227 | AQ10: 46265 | AR10: RETA OP FIN
B11: 3 | C11: 5 | D11: USD | F11: ROBERT NEAL | G11: WILLIAMS JR | M11: RETA | O11: SOLD | P11: 375000 | Q11: =P11*$U$3 -> 6937500 | R11: 135800 | T11: =P11-R11 -> 239200 | U11: =T11*U$3 -> 4425200 | X11: =VLOOKUP(C11,Banorte!F:K,6,FALSE) -> #N/A | Z11: =X11-Y11 -> #N/A | AI11: 46265 | AO11: V05 | AP11: 46227 | AQ11: 46265 | AR11: RETA
B12: 4 | C12: 6 | D12: USD | F12: JASON | G12: TODT | M12: RETA OP FIN | O12: SOLD | P12: 375000 | Q12: =P12*$U$3 -> 6937500 | R12: 133220 | T12: =P12-R12 -> 241780 | U12: =T12*U$3 -> 4472930 | W12: CREDITO RETA | X12: =VLOOKUP(C12,Banorte!F:K,6,FALSE) -> #N/A | Z12: =X12-Y12 -> #N/A | AI12: 46265 | AO12: V06 | AP12: 46227 | AQ12: 46265 | AR12: RETA OP FIN
B13: 5 | C13: 7 | D13: USD | F13: ROBERT ANTHONY | G13: PALMA | M13: RETA OP FIN | O13: SOLD | P13: 375000 | Q13: =P13*$U$3 -> 6937500 | R13: 133220 | T13: =P13-R13 -> 241780 | U13: =T13*U$3 -> 4472930 | W13: CREDITO RETA | X13: =VLOOKUP(C13,Banorte!F:K,6,FALSE) -> #N/A | Z13: =X13-Y13 -> #N/A | AI13: 46265 | AO13: V07 | AP13: 46227 | AQ13: 46265 | AR13: RETA OP FIN
B14: 6 | C14: 8 | D14: USD | F14: MCGREGOR | G14: MARGARET | M14: RETA OP FIN | O14: SOLD | P14: 375000 | Q14: =P14*$U$3 -> 6937500 | R14: 207852.45 | T14: =P14-R14 -> 167147.55 | U14: =T14*U$3 -> 3092229.7 | W14: CREDITO RETA | X14: =VLOOKUP(C14,Banorte!F:K,6,FALSE) -> #N/A | Z14: =X14-Y14 -> #N/A | AI14: 46265 | AO14: V08 | AP14: 46227 | AQ14: 46265 | AR14: RETA OP FIN
B15: 7 | C15: 9 | D15: USD | F15: ROBERT MILES | G15: GILLESPIE | M15: RETA OP FIN | O15: SOLD | P15: 375000 | Q15: =P15*$U$3 -> 6937500 | R15: 133220 | T15: =P15-R15 -> 241780 | U15: =T15*U$3 -> 4472930 | W15: CREDITO RETA | X15: =VLOOKUP(C15,Banorte!F:K,6,FALSE) -> #N/A | Z15: =X15-Y15 -> #N/A | AI15: 46265 | AO15: V09 | AP15: 46227 | AQ15: 46265 | AR15: RETA OP FIN
B16: 126 | C16: 10 | D16: MXN | F16: MANUEL ENRIQUE | G16: GARCIA | H16: GARZA | M16: GENERAL | O16: SOLD | Q16: 13426000 | S16: 3356500 | U16: =Q16-S16 -> 10069500 | X16: =VLOOKUP(C16,Banorte!F:K,6,FALSE) -> #N/A | Z16: =X16-Y16 -> #N/A | AI16: 46265 | AO16: V10 | AP16: 46227 | AQ16: 46265 | AR16: GENERAL
B17: 135 | C17: 11 | D17: MXN | F17: eduardo | G17: BARAJAS | H17: SANCHEZ | M17: GENERAL | O17: SOLD | Q17: 8504475 | S17: 7223803.8 | U17: =Q17-S17 -> 1280671.2 | X17: =VLOOKUP(C17,Banorte!F:K,6,FALSE) -> #N/A | Z17: =X17-Y17 -> #N/A | AI17: 46265 | AO17: V11 | AP17: 46227 | AQ17: 46265 | AR17: GENERAL
B18: 153 | C18: 12 | D18: MXN | F18: JESÃšS RODRIGO | G18: MATA | H18: PAREDES | M18: GENERAL | O18: SOLD | Q18: 8767500 | S18: 2470399 | U18: =Q18-S18 -> 6297101 | X18: =VLOOKUP(C18,Banorte!F:K,6,FALSE) -> #N/A | Z18: =X18-Y18 -> #N/A | AI18: 46265 | AO18: V12 | AP18: 46227 | AQ18: 46265 | AR18: GENERAL
B19: 8 | C19: 13 | D19: USD | F19: CYNTHIA MARY | G19: DICKINS COLLIN SMITH | M19: RETA OP FIN | O19: SOLD | P19: 325000 | Q19: =P19*$U$3 -> 6012500 | R19: 123220 | T19: =P19-R19 -> 201780 | U19: =T19*U$3 -> 3732930 | W19: CREDITO RETA | X19: =VLOOKUP(C19,Banorte!F:K,6,FALSE) -> #N/A | Z19: =X19-Y19 -> #N/A | AI19: 46265 | AO19: V13 | AP19: 46227 | AQ19: 46265 | AR19: RETA OP FIN
B20: 159 | C20: 14 | D20: MXN | F20: FRANCISCO JAVIER | G20: VARGAS | H20: DEL TORO | M20: GENERAL | O20: SOLD | Q20: 8882500 | S20: 2664750 | U20: =Q20-S20 -> 6217750 | X20: =VLOOKUP(C20,Banorte!F:K,6,FALSE) -> #N/A | Z20: =X20-Y20 -> #N/A | AI20: 46265 | AO20: V14 | AP20: 46227 | AQ20: 46265 | AR20: GENERAL
B21: 160 | C21: 15 | D21: MXN | F21: COLIN robert | G21: CARRIE | M21: GENERAL | O21: SOLD | Q21: 8438375 | S21: 6750700 | U21: =Q21-S21 -> 1687675 | X21: =VLOOKUP(C21,Banorte!F:K,6,FALSE) -> #N/A | Z21: =X21-Y21 -> #N/A | AI21: 46265 | AO21: V15 | AP21: 46227 | AQ21: 46265 | AR21: GENERAL
B22: 161 | C22: 16 | D22: MXN | F22: HABSY MARIA | G22: AGUIRRE | H22: KURI | M22: GENERAL | O22: SOLD | Q22: 6381375 | S22: 1915343.8 | U22: =Q22-S22 -> 4466031.2 | X22: =VLOOKUP(C22,Banorte!F:K,6,FALSE) -> #N/A | Z22: =X22-Y22 -> #N/A | AI22: 46265 | AO22: V16 | AP22: 46227 | AQ22: 46265 | AR22: GENERAL
B23: 162 | C23: 17 | D23: MXN | F23: EFRÃ‰N ALBERTO | G23: SÃNCHEZ | H23: CAMPOS | M23: GENERAL | O23: SOLD | Q23: 9621150 | S23: 5500000 | U23: =Q23-S23 -> 4121150 | X23: =VLOOKUP(C23,Banorte!F:K,6,FALSE) -> #N/A | Z23: =X23-Y23 -> #N/A | AI23: 46265 | AO23: V17 | AP23: 46227 | AQ23: 46265 | AR23: GENERAL
B24: 163 | C24: 18 | D24: MXN | F24: GIMER AUGURIO | G24: PIÃ‘A | H24: HERRERA | M24: GENERAL | O24: SOLD | Q24: 9817500 | S24: 4432738 | U24: =Q24-S24 -> 5384762 | X24: =VLOOKUP(C24,Banorte!F:K,6,FALSE) -> #N/A | Z24: =X24-Y24 -> #N/A | AI24: 46265 | AO24: V18 | AP24: 46227 | AQ24: 46265 | AR24: GENERAL
B25: 9 | C25: 19 | D25: USD | F25: MICHAEL | G25: JENSEN | M25: RETA OP FIN | O25: SOLD | P25: 325000 | Q25: =P25*$U$3 -> 6012500 | R25: 162500 | T25: =P25-R25 -> 162500 | U25: =T25*U$3 -> 3006250 | W25: CREDITO RETA | X25: =VLOOKUP(C25,Banorte!F:K,6,FALSE) -> #N/A | Z25: =X25-Y25 -> #N/A | AI25: 46265 | AO25: V19 | AP25: 46227 | AQ25: 46265 | AR25: RETA OP FIN
B26: 164 | C26: 20 | D26: MXN | F26: ADAN | G26: MARTINEZ | H26: VILLA | M26: GENERAL | O26: SOLD | Q26: 10308375 | S26: 7308375 | U26: =Q26-S26 -> 3000000 | X26: =VLOOKUP(C26,Banorte!F:K,6,FALSE) -> #N/A | Z26: =X26-Y26 -> #N/A | AI26: 46265 | AO26: V20 | AP26: 46227 | AQ26: 46265 | AR26: GENERAL
B27: 165 | C27: 21 | D27: MXN | M27: GENERAL | O27: AVAILABLE | U27: =Q27-S27 -> 0 | X27: =VLOOKUP(C27,Banorte!F:K,6,FALSE) -> #N/A | Z27: =X27-Y27 -> #N/A | AI27: 46265 | AO27: V21 | AP27: 46227 | AQ27: 46265 | AR27: GENERAL | AS27: DISPONIBLE
B28: 10 | C28: 301 | D28: USD | F28: GERARD j | G28: HEALEY | M28: RETA OP FIN | O28: SOLD | P28: 209800 | Q28: =P28*$U$3 -> 3881300 | R28: 83916 | T28: =P28-R28 -> 125884 | U28: =T28*U$3 -> 2328854 | W28: CREDITO RETA | X28: =VLOOKUP(C28,Banorte!F:K,6,FALSE) -> #N/A | Z28: =X28-Y28 -> #N/A | AI28: 46244 | AO28: 301 | AP28: 46213 | AQ28: 46244 | AR28: RETA OP FIN
B29: 11 | C29: 302 | D29: USD | F29: CRAIG OLIVER | G29: CHRISTIANSON | M29: RETA OP FIN | O29: SOLD | P29: 209800 | Q29: =P29*$U$3 -> 3881300 | R29: 83918 | T29: =P29-R29 -> 125882 | U29: =T29*U$3 -> 2328817 | W29: CREDITO RETA | X29: =VLOOKUP(C29,Banorte!F:K,6,FALSE) -> #N/A | Z29: =X29-Y29 -> #N/A | AI29: 46244 | AO29: 302 | AP29: 46213 | AQ29: 46244 | AR29: RETA OP FIN
B30: 12 | C30: 303 | D30: USD | F30: VINCENT | G30: FONSECA | M30: RETA OP FIN | O30: SOLD | P30: 209800 | Q30: =P30*$U$3 -> 3881300 | R30: 83916 | T30: =P30-R30 -> 125884 | U30: =T30*U$3 -> 2328854 | W30: CREDITO RETA | X30: =VLOOKUP(C30,Banorte!F:K,6,FALSE) -> #N/A | Z30: =X30-Y30 -> #N/A | AI30: 46244 | AO30: 303 | AP30: 46213 | AQ30: 46244 | AR30: RETA OP FIN
B31: 166 | C31: 304 | D31: MXN | F31: CAMERON ARTHUR | G31: WILKES | M31: GENERAL | O31: SOLD | Q31: 8549000 | S31: 8549000 | U31: =Q31-S31 -> 0 | X31: =VLOOKUP(C31,Banorte!F:K,6,FALSE) -> #N/A | Z31: =X31-Y31 -> #N/A | AI31: 46244 | AO31: 304 | AP31: 46213 | AQ31: 46244 | AR31: GENERAL | AS31: PAGADO
B32: 13 | C32: 305 | D32: USD | F32: JOHN WAYLAND | G32: SLAUGHTER | M32: RETA OP FIN | O32: SOLD | P32: 363500 | Q32: =P32*$U$3 -> 6724750 | R32: 130920 | T32: =P32-R32 -> 232580 | U32: =T32*U$3 -> 4302730 | W32: CREDITO RETA | X32: =VLOOKUP(C32,Banorte!F:K,6,FALSE) -> #N/A | Z32: =X32-Y32 -> #N/A | AI32: 46244 | AO32: 305 | AP32: 46213 | AQ32: 46244 | AR32: RETA OP FIN
B33: 14 | C33: 306 | D33: USD | F33: CAROL ANN | G33: ROBERTS | M33: RETA OP FIN | O33: SOLD | P33: 209800 | Q33: =P33*$U$3 -> 3881300 | R33: 83916 | T33: =P33-R33 -> 125884 | U33: =T33*U$3 -> 2328854 | W33: CREDITO RETA | X33: =VLOOKUP(C33,Banorte!F:K,6,FALSE) -> #N/A | Z33: =X33-Y33 -> #N/A | AI33: 46244 | AO33: 306 | AP33: 46213 | AQ33: 46244 | AR33: RETA OP FIN
B34: 15 | C34: 307 | D34: USD | F34: RANDY NEIL | G34: YEAGER | M34: RETA OP FIN | O34: SOLD | P34: 209800 | Q34: =P34*$U$3 -> 3881300 | R34: 83916 | T34: =P34-R34 -> 125884 | U34: =T34*U$3 -> 2328854 | W34: CREDITO RETA | X34: =VLOOKUP(C34,Banorte!F:K,6,FALSE) -> #N/A | Z34: =X34-Y34 -> #N/A | AI34: 46244 | AO34: 307 | AP34: 46213 | AQ34: 46244 | AR34: RETA OP FIN
B35: 16 | C35: 308 | D35: USD | F35: Robert Glenn | G35: GOOGE | M35: RETA | O35: SOLD | P35: 209800 | Q35: =P35*$U$3 -> 3881300 | R35: 83916 | T35: =P35-R35 -> 125884 | U35: =T35*U$3 -> 2328854 | X35: =VLOOKUP(C35,Banorte!F:K,6,FALSE) -> #N/A | Z35: =X35-Y35 -> #N/A | AI35: 46244 | AO35: 308 | AP35: 46213 | AQ35: 46244 | AR35: RETA
B36: 17 | C36: 309 | D36: USD | F36: JORGE | G36: QUINONES VELEZ | M36: RETA OP FIN | O36: SOLD | P36: 209800 | Q36: =P36*$U$3 -> 3881300 | R36: 83916 | T36: =P36-R36 -> 125884 | U36: =T36*U$3 -> 2328854 | W36: CREDITO RETA | X36: =VLOOKUP(C36,Banorte!F:K,6,FALSE) -> #N/A | Z36: =X36-Y36 -> #N/A | AI36: 46244 | AO36: 309 | AP36: 46213 | AQ36: 46244 | AR36: RETA OP FIN
B37: 18 | C37: 310 | D37: USD | F37: JOSEPH LEONARD | G37: UMIDI | M37: RETA | O37: SOLD | P37: 209800 | Q37: =P37*$U$3 -> 3881300 | R37: 83916 | T37: =P37-R37 -> 125884 | U37: =T37*U$3 -> 2328854 | X37: =VLOOKUP(C37,Banorte!F:K,6,FALSE) -> #N/A | Z37: =X37-Y37 -> #N/A | AI37: 46244 | AO37: 310 | AP37: 46213 | AQ37: 46244 | AR37: RETA
B38: 19 | C38: 311 | D38: USD | F38: NICK DELANO | G38: DE BARMORE | M38: RETA OP FIN | O38: SOLD | P38: 209800 | Q38: =P38*$U$3 -> 3881300 | R38: 199310 | T38: =P38-R38 -> 10490 | U38: =T38*U$3 -> 194065 | W38: CREDITO RETA | X38: =VLOOKUP(C38,Banorte!F:K,6,FALSE) -> #N/A | Z38: =X38-Y38 -> #N/A | AI38: 46244 | AO38: 311 | AP38: 46213 | AQ38: 46244 | AR38: RETA OP FIN | AS38: PAGADO
B39: 20 | C39: 312 | D39: USD | F39: DANNIEL JOHN | G39: JOHNSON | M39: RETA OP FIN | O39: SOLD | P39: 209800 | Q39: =P39*$U$3 -> 3881300 | R39: 83916 | T39: =P39-R39 -> 125884 | U39: =T39*U$3 -> 2328854 | W39: CREDITO RETA | X39: =VLOOKUP(C39,Banorte!F:K,6,FALSE) -> #N/A | Z39: =X39-Y39 -> #N/A | AI39: 46244 | AO39: 312 | AP39: 46213 | AQ39: 46244 | AR39: RETA OP FIN
B40: 21 | C40: 313 | D40: USD | F40: MICHAEL DAVID | G40: LENKER | M40: RETA OP FIN | O40: SOLD | P40: 363500 | Q40: =P40*$U$3 -> 6724750 | R40: 130920 | T40: =P40-R40 -> 232580 | U40: =T40*U$3 -> 4302730 | W40: CREDITO RETA | X40: =VLOOKUP(C40,Banorte!F:K,6,FALSE) -> #N/A | Z40: =X40-Y40 -> #N/A | AI40: 46244 | AO40: 313 | AP40: 46213 | AQ40: 46244 | AR40: RETA OP FIN
B41: 22 | C41: 314 | D41: USD | F41: CARMINE | G41: MITRONI | M41: RETA OP FIN | O41: SOLD | P41: 363500 | Q41: =P41*$U$3 -> 6724750 | R41: 362965 | T41: =P41-R41 -> 535 | U41: =T41*U$3 -> 9897.5 | W41: CREDITO RETA | X41: =VLOOKUP(C41,Banorte!F:K,6,FALSE) -> #N/A | Z41: =X41-Y41 -> #N/A | AI41: 46244 | AO41: 314 | AP41: 46213 | AQ41: 46244 | AR41: RETA OP FIN | AS41: PAGADO
...

Sheet Banorte
K2: =SUBTOTAL(9,K5:K195) -> 653920000
B3: CATALOGO DE CUENTAS | E3: INFORMACION ADICIONAL PARA REPORTES DE COBRANZA
B4: PROYECTO | C4: CUENTA | D4: SUBCUENTA | E4: EDIFICACION | F4: TIPO | G4: TIPO | H4: NIVEL | I4: VISTA | J4: M2 | K4: Valor liberacion
B5: YUCALPETEN E2 | C5: CLIENTES | D5: DEPTO B0301 | E5: BONANZA | F5: B-301 | G5: A2 | H5: 3 | I5: MAR | J5: 117.88 | K5: 2600000
B6: YUCALPETEN E2 | C6: CLIENTES | D6: DEPTO B0302 | E6: BONANZA | F6: B-302 | G6: A5 | H6: 3 | I6: MAR | J6: 117.88 | K6: 2600000
B7: YUCALPETEN E2 | C7: CLIENTES | D7: DEPTO B0303 | E7: BONANZA | F7: B-303 | G7: A3 | H7: 3 | I7: MARINA | J7: 117.88 | K7: 2600000
B8: YUCALPETEN E2 | C8: CLIENTES | D8: DEPTO B0306 | E8: BONANZA | F8: B-306 | G8: A3 | H8: 3 | I8: MARINA | J8: 117.88 | K8: 2600000
B9: YUCALPETEN E2 | C9: CLIENTES | D9: DEPTO B0307 | E9: BONANZA | F9: B-307 | G9: A5 | H9: 3 | I9: MARINA | J9: 117.88 | K9: 2600000
B10: YUCALPETEN E2 | C10: CLIENTES | D10: DEPTO B0308 | E10: BONANZA | F10: B-308 | G10: A2 | H10: 3 | I10: MAR | J10: 117.88 | K10: 2600000
B11: YUCALPETEN E2 | C11: CLIENTES | D11: DEPTO B0309 | E11: BONANZA | F11: B-309 | G11: A4 | H11: 3 | I11: MAR | J11: 117.88 | K11: 2600000
B12: YUCALPETEN E2 | C12: CLIENTES | D12: DEPTO B0310 | E12: BONANZA | F12: B-310 | G12: A2 | H12: 3 | I12: MAR | J12: 117.88 | K12: 2600000
B13: YUCALPETEN E2 | C13: CLIENTES | D13: DEPTO B0311 | E13: BONANZA | F13: B-311 | G13: A5 | H13: 3 | I13: MARINA | J13: 117.88 | K13: 2600000
B14: YUCALPETEN E2 | C14: CLIENTES | D14: DEPTO B0312 | E14: BONANZA | F14: B-312 | G14: A3 | H14: 3 | I14: MARINA | J14: 117.88 | K14: 2600000
B15: YUCALPETEN E2 | C15: CLIENTES | D15: DEPTO B0315 | E15: BONANZA | F15: B-315 | G15: A3 | H15: 3 | I15: MARINA | J15: 117.88 | K15: 2600000
B16: YUCALPETEN E2 | C16: CLIENTES | D16: DEPTO B0316 | E16: BONANZA | F16: B-316 | G16: A5 | H16: 3 | I16: MAR | J16: 117.88 | K16: 2600000
... B195: YUCALPETEN E2 | C195: CLIENTES | D195: DEPTO B1214 | E195: BONANZA | F195: BO-1214 | G195: D PH | H195: 12 | I195: MAR | J195: 303.63 | K195: 7160000

Sheet Vendidos x Ent Obra
B2: EDIFICIO | C2: UNIDADES | D2: SOLD | E2: AVAILABLE | F2: ENT OBRA A POSTV | G2: ENT A CTES | H2: CUST X ENTREG
B3: A | C3: =COUNTIF(Bonanza!$A$7:$A$197,'Vendidos x Ent Obra'!$B3) -> 0 | D3: =COUNTIFS(Bonanza!$A$7:$A$197,'Vendidos x Ent Obra'!$B3,Bonanza!$O$7:$O$197,'Vendidos x Ent Obra'!D$2) -> 0 | E3: =C3-D3 -> 0 | F3: =COUNTIFS(Bonanza!$A$7:$A$197,'Vendidos x Ent Obra'!$B3,Bonanza!#REF!,"ENTREGADO") -> #REF! | G3: =COUNTIFS(Bonanza!$A$7:$A$197,'Vendidos x Ent Obra'!$B3,Bonanza!$AE$7:$AE$197,"ENTREGADO") -> 0 | H3: =COUNTIFS(Bonanza!$A$7:$A$197,'Vendidos x Ent Obra'!$B3,Bonanza!$AE$7:$AE$197,"CUSTODIA") -> 0
B4: B | C4: =COUNTIF(Bonanza!$A$7:$A$197,'Vendidos x Ent Obra'!$B4) -> 0 | D4: =COUNTIFS(Bonanza!$A$7:$A$197,'Vendidos x Ent Obra'!$B4,Bonanza!$O$7:$O$197,'Vendidos x Ent Obra'!D$2) -> 0 | E4: =C4-D4 -> 0 | F4: =COUNTIFS(Bonanza!$A$7:$A$197,'Vendidos x Ent Obra'!$B4,Bonanza!#REF!,"ENTREGADO") -> #REF! | G4: =COUNTIFS(Bonanza!$A$7:$A$197,'Vendidos x Ent Obra'!$B4,Bonanza!$AE$7:$AE$197,"ENTREGADO") -> 0 | H4: =COUNTIFS(Bonanza!$A$7:$A$197,'Vendidos x Ent Obra'!$B4,Bonanza!$AE$7:$AE$197,"CUSTODIA") -> 0
B5: C | C5: =COUNTIF(Bonanza!$A$7:$A$197,'Vendidos x Ent Obra'!$B5) -> 0 | D5: =COUNTIFS(Bonanza!$A$7:$A$197,'Vendidos x Ent Obra'!$B5,Bonanza!$O$7:$O$197,'Vendidos x Ent Obra'!D$2) -> 0 | E5: =C5-D5 -> 0 | F5: =COUNTIFS(Bonanza!$A$7:$A$197,'Vendidos x Ent Obra'!$B5,Bonanza!#REF!,"ENTREGADO") -> #REF! | G5: =COUNTIFS(Bonanza!$A$7:$A$197,'Vendidos x Ent Obra'!$B5,Bonanza!$AE$7:$AE$197,"ENTREGADO") -> 0 | H5: =COUNTIFS(Bonanza!$A$7:$A$197,'Vendidos x Ent Obra'!$B5,Bonanza!$AE$7:$AE$197,"CUSTODIA") -> 0
B6: D | C6: =COUNTIF(Bonanza!$A$7:$A$197,'Vendidos x Ent Obra'!$B6) -> 0 | D6: =COUNTIFS(Bonanza!$A$7:$A$197,'Vendidos x Ent Obra'!$B6,Bonanza!$O$7:$O$197,'Vendidos x Ent Obra'!D$2) -> 0 | E6: =C6-D6 -> 0 | F6: =COUNTIFS(Bonanza!$A$7:$A$197,'Vendidos x Ent Obra'!$B6,Bonanza!#REF!,"ENTREGADO") -> #REF! | G6: =COUNTIFS(Bonanza!$A$7:$A$197,'Vendidos x Ent Obra'!$B6,Bonanza!$AE$7:$AE$197,"ENTREGADO") -> 0 | H6: =COUNTIFS(Bonanza!$A$7:$A$197,'Vendidos x Ent Obra'!$B6,Bonanza!$AE$7:$AE$197,"CUSTODIA") -> 0
B7: E | C7: =COUNTIF(Bonanza!$A$7:$A$197,'Vendidos x Ent Obra'!$B7) -> 0 | D7: =COUNTIFS(Bonanza!$A$7:$A$197,'Vendidos x Ent Obra'!$B7,Bonanza!$O$7:$O$197,'Vendidos x Ent Obra'!D$2) -> 0 | E7: =C7-D7 -> 0 | F7: =COUNTIFS(Bonanza!$A$7:$A$197,'Vendidos x Ent Obra'!$B7,Bonanza!#REF!,"ENTREGADO") -> #REF! | G7: =COUNTIFS(Bonanza!$A$7:$A$197,'Vendidos x Ent Obra'!$B7,Bonanza!$AE$7:$AE$197,"ENTREGADO") -> 0 | H7: =COUNTIFS(Bonanza!$A$7:$A$197,'Vendidos x Ent Obra'!$B7,Bonanza!$AE$7:$AE$197,"CUSTODIA") -> 0
B9: TOTALES | C9: =SUM(C3:C8) -> 0 | D9: =SUM(D3:D8) -> 0 | E9: =SUM(E3:E8) -> 0 | F9: =SUM(F3:F8) -> #REF! | G9: =SUM(G3:G8) -> 0 | H9: =SUM(H3:H8) -> 0
F10: =IF(F9=SUM(G9:H9),"OK","ERROR") -> #REF!

Sheet CANCELACIONES
A1: DEPTO | B1: TYPE | C1: NOMBRE (S) | D1: APELLIDO 1 | E1: APELLIDO 2 | F1: ALIAS / RAZON SOCIAL | G1: @mail | H1: LADA | I1: Telefono | J1: TIPO CLIENTE | K1: TIPO CONTRATO | L1: STATUS SISTEMA | M1: Monto Venta | N1: PAGADO | O1: SALDO | P1: SALDO MN | Q1: FECHA COBRO SALDO | R1: FORMA PAGO | S1: VALOR LIBERACION | T1: PAGADO LIBERACION | U1: X PAGAR | V1: FECHA LIBERACIÓN | W1: ESCRITURACION | X1: FECHA ESCRITURACION | Y1: NOTARIA | Z1: STATUS SOS | AA1: FECHA SEGÚN CONTRATO | AB1: FECHA SOS | AC1: FECHA ENTREGA OBRA | AD1: FECHA ENTREGA CLIENTE | AE1: COMENTARIOS | AF1: TICKET
